Workbook

Sheet 사용법
A1: 올투게더나우 B2B 영업 리스트 (한국 영업 × 중국 소싱 파트너 모델)
A3: 시트 구성
A4: 영업리스트 | B4: 컨택 대상 업체 전체. 노란색 칸(1차연락일~메모)만 직접 채우면 됩니다.
A5: 요약 | B5: 카테고리·우선순위별 업체 수와 연락 진행 현황이 자동 집계됩니다.
A6: 영업멘트 | B6: 전화·이메일 첫 컨택용 스크립트 초안.
A8: 우선순위 뜻
A9: 상 | B9: 중국 소싱 조직이 약하거나 없고, 굿즈/OEM 물량이 꾸준한 곳. 먼저 연락.
A10: 중 | B10: 가능성은 있으나 규모·소싱 방식이 불명확. 2차 연락.
A11: 하 | B11: 중국 자체 공장·지사를 이미 보유(경쟁사). 정보 수집용, 컨택 후순위.
A12: 회수 대상 | B12: 리자위와 결별한 前 파트너(함석민)가 응대하던 거래처. 리자위 쪽 생산 실적이 있으므로 최우선 컨택. 리스트 맨 위에 배치.
A14: 주의사항
A15: 1 | B15: 연락처는 각 회사가 홈페이지에 영업 목적으로 공개한 대표번호·대표메일·문의채널만 수집했습니다.
A16: 2 | B16: 빈칸은 홈페이지에서 확인이 안 된 항목입니다. 전화 걸 때 직접 물어보고 채우세요.
A17: 3 | B17: 연락 전 출처URL을 한 번 열어 현재도 영업 중인지, 번호가 바뀌지 않았는지 확인하세요.
A18: 4 | B18: 1차연락결과는 드롭다운(통화/메일발송/관심/견적요청/거절/부재/재연락)에서 고르면 요약 시트에 자동 집계됩니다.
A20: 조사일 | B20: 2026-09-09 (웹 공개정보 기준)

Sheet 영업리스트
A1: 번호 | B1: 우선순위 | C1: 업체명 | D1: 카테고리 | E1: 홈페이지 | F1: 대표전화 | G1: 이메일 | H1: 문의채널 | I1: 소재지 | J1: 주요취급품목 | K1: 중국자체소싱망 | L1: 선정이유 | M1: 출처URL | N1: 1차연락일 | O1: 연락방법 | P1: 담당부서/담당자 | Q1: 1차연락결과 | R1: 후속조치 | S1: 다음연락일 | T1: 메모
A2: 1 | B2: 상 | C2: (주)비투비앤씨 | D2: 회수 대상(前 파트너 거래처) | E2: https://btobnc.co.kr/ | F2: 02-745-9650 | G2: btobnc@daum.net | H2: 담당: 이병호 (휴대폰은 대표님 보유 메일 서명 참조) | I2: 서울 금천구 가산동(대성디폴리스 B동 1806호) | J2: 판촉물·굿즈 벤더(추정), 세부 품목 확인 필요 / 공개정보: B2B 소싱 플랫폼 기업. 기업 대상 굿즈·PB(자체브랜드)·판촉물(PGI) 기획/개발/소싱 컨설팅, 시즌별 판촉 사은품 디자인·제조, BtoE(임직원몰) 기획·운영. 2008년 6월 설립, 소기업(2023년 매출 약 127.9억, 직원 7명). 팩스 02-745-9649, 사업자번호 101-86-40347. | K2: 약함(前 파트너 함석민을 통해 중국 생산 진행하던 거래처) | L2: 리자위와 결별한 前 파트너(함석민)가 응대하던 거래처로, 리자위 쪽 생산 실적을 근거로 직접 회수 가능. | M2: 함석민 경유 메일 서명(2024) ; https://btobnc.co.kr/contact ; https://www.jobplanet.co.kr/companies/154239/landing/%EB%B9%84%ED%88%AC%EB%B9%84%EC%95%A4%EC%94%A8 ; https://www.jobkorea.co.kr/recruit/co_read/c/choish73
A3: 2 | B3: 상 | C3: 스펙트럼비즈 | D3: 회수 대상(前 파트너 거래처) | G3: spbiz1@hanmail.net | H3: 담당: 김상현 대표 / 메일 회신 이력 있음(2024.02 클립펜·온습도계 건) | J3: 소량 판촉물(클립펜 2종 각 500개, 온습도계 500개, 팬톤 컬러 인쇄) / 공개정보: 검색상 (주)스펙트럼비즈(매장광고 POSM, LED 라이트패널 Wtalk)가 있으나 동일 회사인지 미확인 | K3: 약함(前 파트너 함석민을 통해 중국 생산 진행하던 거래처) | L3: 500개 단위 소량 판촉물을 중국 생산하던 거래처. 소량·팬톤 인쇄 대응 가능함을 강조하면 회수 가능성 높음. | M3: 함석민 경유 메일(2024.02.27) ; http://www.04uk.com/bbs/board.php?bo_table=03&wr_id=34299 ; https://rainbowdeco.com/contact ; https://abnexo.gobizkorea.com/user/goods/frontGoodsDetail.do?goods_no=GS2021101807985
A4: 3 | B4: 상 | C4: 지티비(GTB) | D4: 회수 대상(前 파트너 거래처) | G4: gtb111@daum.net | H4: 메일 회신 이력 있음(2023.11 오스템임플란트 캐릭터 굿즈 건) | J4: 기업 캐릭터 굿즈 제작 중개(오스템임플란트 브랜드디자인팀 발주 → 중국 생산) | K4: 약함(前 파트너 함석민을 통해 중국 생산 진행하던 거래처) | L4: 오스템임플란트 같은 대기업 디자인팀 발주를 받아 생산처에 넘기는 전형적 벤더. 캐릭터 굿즈 반복 물량 기대. | M4: 함석민 경유 메일(2023.11.10)
A5: 4 | B5: 상 | C5: 하나라인(hanaLine Co., Ltd.) | D5: 회수 대상(前 파트너 거래처) | F5: 02-929-6060 | H5: 담당: 양경호 Director / Fax 02-929-6092 | I5: 서울 동대문구 용두동 | J5: 판촉물·봉제·인쇄 벤더(추정), 세부 품목 확인 필요 | K5: 약함(前 파트너 함석민을 통해 중국 생산 진행하던 거래처) | L5: 동대문 소재 벤더로 前 파트너 경유 물량이 있었던 곳. 회사 대표번호가 확보돼 있어 바로 전화 가능. | M5: 함석민 경유 메일 서명(2024)
A6: 5 | B6: 중 | C6: 강정호(회사명 미확인, SSGP 박스 건) | D6: 회수 대상(前 파트너 거래처) | G6: scott7015@naver.com | H6: 메일 회신 이력 있음(2024.02 SSGP 패키지 박스 도면 건) | J6: 브랜드 패키지 박스(SSGP PK outline ai/pdf 도면 전달) / 공개정보: SSGP는 화장품이 아니라 스테인리스(SUS304) 주방 조리도구 브랜드. 국내 온라인몰(SSG.COM/신세계몰, 한샘몰, YES24, 옥션, 다나와, 체어마트, 케이트왈츠 등)에서 '독일 SSGP 스텐 조리도구'로 표기되어 판매됨(스텐 머그/드럼컵, 국자, 집게, 거품기, 채반, 티망, 셰프나이프, 계량컵 등). 국내에서 SSGP 제품을 판매하는 업체로 (주)애플박스(경기 파주시 탄현면 검산로361번길 64, 031-8071-0707, 사업자 388-87-00648)와 (주)호민상사(대구 달서구, 사업자 530-87-02140)가 확인되나 공식 수입원/브랜드 소유 회사는 미확인. 해외 도매사이트(sunsky-online)에서도 SSGP 제품이 유통되어 실제 원산지/브랜드 본사는 검색으로 확정되지 않음. | K6: 약함(前 파트너 함석민을 통해 중국 생산 진행하던 거래처) | L6: 패키징 박스 중국 생산 건을 넘기던 발주자. 회사명·역할(브랜드 담당자인지 중개 벤더인지) 확인 후 접근. | M6: 함석민 경유 메일(2024.02.21) ; https://www.yes24.com/Product/Goods/97782001 ; https://store.hanssem.com/goods/821760 ; http://chairmart.co.kr/category/%EB%AA%85%ED%92%88%EC%A3%BC%EB%B0%A9-ssgp/1006/ ; https://katewaltz.co.kr/category/ssgp/209/ ; https://www.ssg.com/search.ssg?query=ssgp%EC%8A%A4%ED%85%90
A7: 6 | B7: 상 | C7: 바잇미((주)바잇미) | D7: OEM 온라인브랜드·패키징 | E7: https://www.biteme.co.kr | F7: 070-4188-1824 | H7: https://www.bizbite.me/ (B2B 사업자전용몰) | I7: 서울 강남구 | J7: 반려동물 장난감·의류·용품(자체 브랜드), B2B 도매·해외판매 | K7: 불명(자체 공장 언급 없음, 자체 브랜드 기획·판매 중심) | L7: 자체 브랜드 반려용품을 기획하고 B2B·글로벌까지 유통하는 업체로 중국 OEM 제조 파트너가 필요한 구조다. | M7: https://www.bizbite.me/
A8: 7 | B8: 상 | C8: 박스마스터 | D8: OEM 온라인브랜드·패키징 | E8: https://boxmaster.co.kr | F8: 1877-8830 | G8: service@boxmaster.co.kr | H8: https://boxmaster.co.kr/whatbm/location | I8: 서울 | J8: 브랜드 패키지 박스 제작, 맞춤 패키지 컨설팅 | K8: 약함(국내 패키지 컨설팅·제조 중심, 중국 소싱망 언급 없음) | L8: 패키지 컨설팅형 업체로 특수 사양 박스·부자재를 중국에서 조달할 외부 파트너가 필요할 수 있다. | M8: https://boxmaster.co.kr/whatbm/location
A9: 8 | B9: 상 | C9: 박스컴퍼니 | D9: OEM 온라인브랜드·패키징 | E9: https://www.boxcompany.co.kr | F9: 02-452-8887 | G9: boxcompany7@naver.com | H9: https://boxcompany.co.kr/contact | I9: 서울 | J9: 소량(100개~) 커스텀 패키지 박스 제작 | K9: 약함(국내 소량 제작 중심, 중국 소싱망 언급 없음) | L9: 소량 커스텀 박스 업체로 대량 주문이나 파우치·쇼핑백 등 특수 패키지는 중국 소싱이 필요할 수 있다. | M9: https://boxcompany.co.kr/contact
A10: 9 | B10: 상 | C10: 생활공작소((주)생활공작소) | D10: OEM 온라인브랜드·패키징 | E10: https://www.saengong.com | H10: https://m.gmarket.co.kr/n/minishop/livingcrafts/sellerinfo / 개인 메일로 보여 제외, 대표 메일 확인 필요 | I10: 서울 영등포구 | J10: 세제·비누·제습제 등 생활용품, 잡화, 반려동물용품 | K10: 불명(자체 공장 언급 없음, 기획·브랜딩 중심 생활용품 브랜드) | L10: 생활용품·잡화 다품종을 외주 생산으로 전개하는 대표적 온라인 브랜드로 중국 OEM 소싱 파트너 수요가 있다. | M10: https://m.gmarket.co.kr/n/minishop/livingcrafts/sellerinfo
A11: 10 | B11: 상 | C11: 패커티브 | D11: OEM 온라인브랜드·패키징 | E11: https://packative.com | G11: hello@packative.com | H11: https://packative.com/en/custom-quotation | I11: 서울 영등포구 | J11: 맞춤 패키지 박스 온라인 주문제작(AI 실시간 견적·3D 미리보기) | K11: 약함(국내 온라인 박스 제작 플랫폼, 중국 소싱망 언급 없음) | L11: 온라인 박스 제작 플랫폼으로 쇼핑백·파우치 등 품목 확장 시 중국 생산 파트너가 필요할 수 있다. | M11: https://help.packative.com/
A12: 11 | B12: 상 | C12: 페스룸((주)비엠스마일) | D12: OEM 온라인브랜드·패키징 | E12: https://pethroom.com | H12: 카카오톡채널 https://pf.kakao.com/_rVWpj / 개인 메일로 보여 제외, 대표 메일 확인 필요 | I12: 서울 강남구 | J12: 반려동물 욕실·위생용품, 의류·액세서리, 반려동물 라이프스타일 용품 | K12: 불명(자체 공장 언급 없음, 소규모 반려용품 제작에서 시작한 브랜드) | L12: 자체 공장 없이 다품종 반려용품을 기획·판매하는 온라인 브랜드로 중국 OEM 생산 파트너 수요가 크다. | M12: https://pethroom.com/
A13: 12 | B13: 상 | C13: 하밋(HAMIT) | D13: OEM 온라인브랜드·패키징 | E13: https://hamit.kr | H13: https://hamit.kr/ | J13: 반려동물 하우스·가구형 휴식 공간(룩앳미 하우스), 반려동물 생활용품 | K13: 약함(원단·원목·철제·봉제 등 7개 외부 제조사 협업으로 생산, 자체 공장 없음) | L13: 다수 외주 제조사에 의존해 제품을 만드는 디자인 중심 브랜드라 원가 절감을 위한 중국 OEM 파트너 수요가 높다. | M13: https://openads.co.kr/content/contentDetail?contsId=17861
A14: 13 | B14: 상 | C14: (주)온오프마켓 (온오프판촉물) | D14: 관공서·학교·금융·프랜차이즈 판촉 납품업체 | E14: https://pr.onoffmarket.com/ | F14: 1544-5269 | G14: onoff@onoffmarket.com | H14: https://www.onoffmarket.com/ (온오프마켓 본몰), https://store.onoffmarket.com/ | I14: 고양 일산동구 | J14: 단체 기념품·답례품·창립기념품·임직원선물·비즈니스선물, 위생용품·안전용품 (여성기업 공공기관 우선구매대상) | K14: 불명(검색결과에 중국 공장/지사 언급 없음) | L14: 여성기업 인증으로 공공기관 우선구매 대상에 등록된 판촉·안전·위생용품 종합 유통사로 공공 납품 물량 대응을 위한 중국 소싱 파트너 수요가 높을 것으로 판단됨. | M14: https://bizno.net/article/1058805007
A15: 14 | B15: 상 | C15: 판촉물도매백화점 (판촉물인쇄기프트 / REDLOOZ) | D15: 관공서·학교·금융·프랜차이즈 판촉 납품업체 | E15: https://87dept.com/ | G15: 87@redlooz.co.kr | H15: 전화번호 형식 의심(015-8504-6667), 홈페이지에서 확인 필요 | I15: 서울 | J15: 판촉물 대량구매 도매, 기념품·답례품·사은품 인쇄 제작 (차량용 디퓨저, 모자, 담요세트, 스카프, 지압기, 자개USB 등) | K15: 불명(검색결과에 중국 공장/지사 언급 없음; 도매상품 중심) | L15: 도매 대량구매를 전면에 내세우고 차량용품·모자·스카프 등 중국 생산 비중이 높은 범용 품목을 다수 취급해 안정적인 중국 소싱 파트너 수요가 클 것으로 판단됨. | M15: https://87dept.com/
A16: 15 | B16: 상 | C16: (주)서울부스애드컴 | D16: 광고·BTL·행사대행사 | E16: https://www.seouladcom.co.kr | F16: 02-6959-4488 | G16: seoul6004@naver.com | H16: https://seoulpr.co.kr/CONTACT | I16: 서울 영등포구 | J16: 전시부스(목공·블럭·옥타늄·트러스), 전시기획, 컨퍼런스·이벤트 부스, 포토존, 축제·행사 기획 | K16: 약함(전시부스 기획·시공 전문, 중국 거점 언급 없음) | L16: 전국 전시장 지정 부스 기획업체로 전시·행사 건수가 많아 부스 연출 소품과 행사 판촉물을 반복 조달하므로 중국 생산·검수·운송 일괄 파트너의 가치가 높다. | M16: https://www.seouladcom.co.kr/ ; https://www.114.co.kr/search/detail?comp_id=1778158&comp_tp_cd=INT&upjong_cd=839920
A17: 16 | B17: 상 | C17: (주)조인트크리에이티브 | D17: 광고·BTL·행사대행사 | E17: https://www.jcccom.co.kr | F17: 02-3443-2631 | G17: jcc2713@jcccom.co.kr | H17: https://jcccom.co.kr/sub.php (견적·상담 070-8146-3402) | I17: 서울 강남구 | J17: 이벤트 프로모션(BTL), 팝업스토어, 전시·부스, 시즌 프로모션, 무대행사, 온·오프라인 통합 마케팅 | K17: 불명(자체 브랜드 제품(이어프리 마스크밴드) 제작 이력은 있으나 중국 지사·공장 언급 없음) | L17: 2001년 설립된 온·오프라인 통합 에이전시로 팝업스토어·시즌 프로모션 등 BTL 행사를 상시 수행하며 자체 굿즈 기획 경험까지 있어 중국 생산 소싱 파트너와 결합 효과가 크다. | M17: https://www.jcccom.co.kr/ ; https://jcccom.co.kr/sub.php?pageState=product_btl
A18: 17 | B18: 상 | C18: (주)크림커뮤니케이션 | D18: 광고·BTL·행사대행사 | E18: http://www.creamcomm.co.kr | F18: 02-542-2671 | G18: soda@creamcomm.co.kr | H18: https://www.creamsoda.co.kr/cs/01/ | I18: 서울 강남구 | J18: 기업행사, 콘서트, 축제, 전시, 프로모션·이벤트, 사회공헌 행사, 콘텐츠·디자인 | K18: 약함(순수 BTL 대행사, 중국 지사·공장 언급 없음) | L18: 프로모션·이벤트 사업부가 대기업 행사를 연간 수백 건 수행하는 BTL 전문 대행사로, 행사별 굿즈·기념품·판촉물을 외주 제작에 의존하므로 중국 소싱 파트너 수요가 높다. | M18: https://www.creamsoda.co.kr/story/03/v/39 ; https://www.114.co.kr/search/detail?comp_id=973606&comp_tp_cd=INT&upjong_cd=711000
A19: 18 | B19: 상 | C19: 가현기획 | D19: 광고·BTL·행사대행사 | E19: https://gahyun.kr | F19: 031-423-6684 | G19: 6684@gahyun.kr | H19: https://gahyun.kr/about/overview.asp | I19: 경기 안양시 동안구 | J19: 전시회·박람회 부스 및 기업홍보관 설계·시공·운영, 컨벤션, 워크숍, 사내행사 기획·제작 | K19: 약함(국내 전시·행사 제작 대행, 중국 공장·지사 언급 없음) | L19: 전시부스 시공과 컨벤션·사내행사를 함께 대행하며 세종·안양 2개 거점을 운영하는 중견 기획사로, 행사 기념품·홍보물 물량이 꾸준해 중국 생산 파트너 활용 여지가 크다. | M19: https://gahyun.kr/about/overview.asp ; https://www.saramin.co.kr/zf_user/company-info/view/csn/VVptZktVaXp3UStyOHAzeFNWUU1OQT09/company_nm/%EA%B0%80%ED%98%84%EA%B8%B0%ED%9A%8D
A20: 19 | B20: 상 | C20: 바나나팩토리 | D20: 소규모 판촉물·패키징 중개벤더 | E20: https://bananafactory.kr | F20: 1522-3852 | H20: https://bananafactory.kr/category/%ED%8C%90%EC%B4%89%EB%AC%BC/344/ | I20: 서울 동대문구 청량리동 | J20: 판촉물(마이보틀·텀블러·장바구니·인주함 등), 광고용품·POP소품·다이어리 소량 100개~ 주문제작 | K20: 불명 — 자체 공장·중국 소싱 언급 없음 | L20: 동대문 소재 개인사업자 판촉물 쇼핑몰로 100개 단위 소량 로고 인쇄 판촉물을 취급해 중국 OEM 소싱 협업 적합. | M20: https://bananafactory.kr/product/%ED%8C%90%EC%B4%89%EB%AC%BC-%ED%99%8D%EB%B3%B4-%EC%9D%B8%EC%87%84-%EB%A7%88%EC%9D%B4%EB%B3%B4%ED%8B%80500ml-%EC%A3%BC%EB%AC%B8%EC%A0%9C%EC%9E%91-100%EA%B0%9C/50379/
A21: 20 | B21: 상 | C21: 박스메이커스(팩토리엠) | D21: 소규모 판촉물·패키징 중개벤더 | E21: https://www.boxmakers.co.kr | F21: 02-2263-9275 | G21: make@factorym.co.kr | H21: https://www.boxmakers.co.kr/portfolio | I21: 서울 중구 퇴계로(충무로 인근) | J21: 브랜드 패키지 박스·골판지합지박스·손잡이박스 주문제작 | K21: 불명 — 자체 공장·중국 소싱 언급 없음 | L21: 충무로 인쇄골목 인근 개인사업자 규모의 패키지 박스 중개 벤더로 브랜드 박스 소량 주문을 외주 생산하는 타깃. | M21: https://boxmakers.co.kr/
A22: 21 | B22: 상 | C22: 신시어리 | D22: 소규모 판촉물·패키징 중개벤더 | E22: https://sincerely.one | F22: 070-7169-1306 | G22: ask@sincerely.one | H22: https://sincerely.one/faq | I22: 서울 성동구 | J22: 브랜드 굿즈(볼캡·의류·문구·리빙), 기업 판촉·선물용 굿즈 | K22: 불명 — 사이트에 자체 공장·중국 지사 언급 없음 | L22: 성수 기반 소규모 브랜드 굿즈 스튜디오로 기업 마케팅팀 대상 소량 커스텀 굿즈를 기획·중개하는 전형적 타깃. | M22: https://sincerely.one/about
A23: 22 | B23: 상 | C23: 에이블밤부 | D23: 소규모 판촉물·패키징 중개벤더 | E23: https://able-bamboo.co.kr | F23: 031-976-9487 | G23: able-bamboo@able-bamboo.com | H23: https://able-bamboo.co.kr/product/list.html?cate_no=467 | I23: 경기 파주시 | J23: 기업 브랜드 굿즈, 친환경 키트·가방, 로고 장우산 등 기업 판촉물 | K23: 불명 — 자체 공장·중국 소싱 언급 없음 | L23: 파주 소재 기업 브랜드 굿즈 제작 전문 소규모 법인으로 대기업 로고 굿즈를 수주해 외주 생산하는 전형적 타깃. | M23: https://able-bamboo.co.kr/
A24: 23 | B24: 상 | C24: 엠유플랜박스 | D24: 소규모 판촉물·패키징 중개벤더 | E24: https://muplanbox.com | F24: 02-6409-6813 | G24: muplanbox@naver.com | H24: https://muplanbox.com/shopinfo/company.html | I24: 서울 성동구 성수동 | J24: 포장박스·칼라박스·싸바리박스·골판지박스 소량 제작, 브랜드 패키지 | K24: 불명 — 자체 공장·중국 소싱 언급 없음 | L24: 성수동 소규모 패키지 제작 브랜드로 소량 브랜드 박스 수요를 받아 외주 생산하는 구조라 중국 패키지 소싱 협업 여지가 큼. | M24: https://muplanbox.com/shopinfo/company.html
A25: 24 | B25: 상 | C25: 연패키지 | D25: 소규모 판촉물·패키징 중개벤더 | E25: https://www.yeonpack.com | F25: 02-6956-1918 | G25: y_pack30@naver.com | H25: https://www.yeonpack.com/box | I25: 서울 중구 을지로 | J25: 화장품 단상자·디저트박스·선물박스·친환경 패키지 주문제작 | K25: 불명 — 자체 공장·중국 소싱 언급 없음 | L25: 을지로 인쇄골목 소재 개인사업자 규모의 패키지 중개 벤더로 브랜드 박스 소량 주문을 외주 생산하는 타깃. | M25: https://www.yeonpack.com/
A26: 25 | B26: 상 | C26: (주)더플러스 (요가몰 YOGAMALL) | D26: 스포츠·헬스·재활용품 유통사/OEM브랜드 | E26: https://yogamall.co.kr | F26: 031-947-0808 | G26: tobe@theplus.biz | H26: https://yogamall.co.kr | I26: 경기 파주시 | J26: 요가·필라테스 매트, 소도구, 리포머, 재활운동 용품, 프랭클린메소드 교육 (요가원·스튜디오 납품) | K26: 약함(요가·필라테스 전문 유통몰, 자체 공장 정보 없음) | L26: 요가원·필라테스 스튜디오 대상 전문 유통몰로 매트·소도구·재활용품 PB 개발 시 외부 중국 OEM 파트너가 필요함. | M26: https://yogamall.co.kr
A27: 26 | B27: 상 | C27: (주)브라이즈 (에이더 AIDER) | D27: 스포츠·헬스·재활용품 유통사/OEM브랜드 | E27: https://aidershop.com | F27: 1566-3175 | G27: aider@bryze.kr | H27: https://m.aidershop.com/article/qa/6/ | I27: 서울 금천구 | J27: 무릎·손목·팔꿈치·발목 보호대, 스포츠 테이핑 등 관절 보호대 전문 브랜드 (물리치료사 개발) | K27: 불명(브랜드 기획·개발 중심, 자체 공장 여부 미공개) | L27: 보호대 전문 온라인 브랜드로 물리치료사 기획 제품을 외주 생산하는 구조로 보여 보호대 OEM 제조 파트너와의 협업 적합성이 매우 높음. | M27: https://aidershop.com
A28: 27 | B28: 상 | C28: (주)앳플리 (ATFLEE) | D28: 스포츠·헬스·재활용품 유통사/OEM브랜드 | E28: https://atflee.com | F28: 02-3445-7877 | G28: sales@atflee.com | H28: https://atflee.com/shopinfo/guide.html | I28: 서울 강남구 | J28: 요가매트·필라테스매트·스마트 체성분 체중계·홈트레이닝 용품 (자체 브랜드 앳플리, 무신사·삼성 SmartThings 입점) | K28: 약함(디자인·앱 중심 온라인 브랜드, 자체 공장 정보 없음) | L28: 자체 공장 없이 브랜드·앱 중심으로 요가매트 등 홈트 용품을 운영하는 전형적인 OEM 브랜드로 중국 소싱 파트너 수요가 큼. | M28: https://atflee.com/shopinfo/guide.html
A29: 28 | B29: 상 | C29: (주)우성레포츠 (아리프 ALEAF) | D29: 스포츠·헬스·재활용품 유통사/OEM브랜드 | E29: https://aleafsports.com | F29: 031-527-2338 | G29: aleaf@wsleports.com | H29: https://aleafsports.com/faq | I29: 경기 남양주시 오남읍 | J29: 요가매트·폼롤러·짐볼·허리보호대·웨이트/홈트 운동기구·키즈스포츠 용품 (자체 브랜드 아리프) | K29: 불명(온라인 브랜드 운영, 자체 공장 정보 미공개) | L29: 요가·필라테스·홈트 소도구를 자체 브랜드로 온라인 판매하며 허리보호대 등 보호대 라인까지 취급해 중국 OEM 소싱 파트너가 필요할 가능성이 높음. | M29: https://aleafsports.com/Privacy
A30: 29 | B30: 상 | C30: (주)코리아스포츠 (아이워너 IWANNA) | D30: 스포츠·헬스·재활용품 유통사/OEM브랜드 | E30: https://korspo.com | F30: 031-573-3313 | G30: k-korspo@naver.com | H30: https://www.korea-sports.co.kr/contact | I30: 경기 남양주시 오남읍 | J30: 폼롤러(EVA/EPP)·마사지볼·마사지스틱·무릎보호대·운동밴드·헬스소도구 (자체 브랜드 아이워너, 프로-스펙스 라이선스) | K30: 불명(자체 브랜드 제조·유통사이나 국내/중국 공장 보유 여부 사이트 확인 불가) | L30: 폼롤러·마사지볼·보호대 등 수십 종의 자체 브랜드 품목을 운영하는 종합 헬스소도구 유통사로 품목 확장·원가 절감을 위한 중국 OEM 파트너 수요가 큼. | M30: https://korspo.com/shopinfo/company.html
A31: 30 | B31: 상 | C31: SJ코리아 | D31: 스포츠·헬스·재활용품 유통사/OEM브랜드 | E31: http://www.sjkorea.co.kr | H31: http://www.sjkorea.co.kr | J31: 정형외과용 소모품(물리치료/통증치료, 캐스트/스프린트, 브레이스·보호대) | K31: 불명(정형외과 소모품 유통, 제조 정보 미확인) | L31: 정형외과·물리치료실 대상 브레이스·보호대 소모품 전문 유통사로 의료용 보호대 OEM 공급 파트너 수요가 직접적임. | M31: http://www.sjkorea.co.kr/shop/goods/goods_list.php?category=009003006
A32: 31 | B32: 상 | C32: 메디브랜드(병원마켓) / (주)이을커뮤니케이션아임 | D32: 제약·의료·치과 판촉물 벤더 | E32: https://www.medibrand.co.kr/ | F32: 1666-6973 / 070-4150-1731 | G32: medibrand@naver.com | H32: https://www.medibrand.co.kr/service/cooperation.php | I32: 서울 서초구 | J32: 병·의원/치과 개원패키지, 판촉물, 명함, 쇼핑백, 캘린더, 의료진 포스터 | K32: 불명 (자체 중국공장·지사 언급 없음, 병원 디자인·인쇄 위주) | L32: 900개 이상 병·의원 런칭 실적의 병원·치과 전문 디자인마켓으로 판촉물·개원패키지를 취급해 중국 생산 굿즈 공급 협업 여지가 큼. | M32: https://www.medibrand.co.kr/service/cooperation.php
A33: 32 | B33: 상 | C33: 하이어기프트 | D33: 제약·의료·치과 판촉물 벤더 | E33: https://cases.higher-gift.com/ | F33: 1533-4855 | G33: highergift@naver.com | H33: https://cases.higher-gift.com/contact/ | J33: 기업·관공서·학교·병원·단체 판촉물·기념품 (제품 선정~인쇄·포장·납품) | K33: 불명 (자체 공장·중국지사 언급 없음) | L33: 병원 판촉물 납품사례를 별도 사이트로 운영하는 소규모 중개 벤더로 자체 공장이 없어 중국 생산 파트너 수요가 있을 것으로 판단됨. | M33: https://cases.higher-gift.com/contact/
A34: 33 | B34: 상 | C34: 매일매일디자인 | D34: 캐릭터·IP·팬굿즈 기획사 | E34: https://www.elmogoon.com/ | G34: elshop@naver.com | H34: https://www.elmogoon.com/ (홈페이지 문의) | J34: IP 캐릭터 굿즈 기획·제작, 굿즈·패키지 OEM, 브랜딩 | K34: 불명(디자인 스튜디오, 생산 거점 언급 없음) | L34: IP 캐릭터 굿즈와 패키지 OEM을 기획하는 소규모 디자인 스튜디오로 제조는 전량 외주라 중국 소싱 파트너 필요성이 크다. | M34: https://www.elmogoon.com/ ; https://www.facebook.com/elmogoon0980/
A35: 34 | B35: 상 | C35: 엑스디컨스트럭트(XDT) | D35: 캐릭터·IP·팬굿즈 기획사 | E35: https://xdeconstruct.com/ | G35: xd@xdeconstruct.com | H35: https://xdeconstruct.com/ (온라인 제작 문의) | I35: 서울 중구 | J35: 아이돌·브랜드 굿즈 OEM/ODM(금속 키링, 주얼리, 헤어 액세서리, 패키지), 소량·대량 제작 | K35: 불명(기획·샘플·생산·검수·납품 일괄 진행 표기, 자체 공장·중국 거점 언급 없음) | L35: 아이돌 MD용 금속 키링·주얼리 등 중국 생산 의존도가 높은 품목을 OEM/ODM으로 기획하는 소규모 업체라 안정적인 중국 소싱 파트너가 유용하다. | M35: https://m.xdeconstruct.com/product/list_thumb.html?cate_no=42 ; https://xdeconstruct.com/
A36: 35 | B36: 상 | C36: 클로스업(ClawsUp) | D36: 캐릭터·IP·팬굿즈 기획사 | E36: https://clawsup.com/ | H36: https://clawsup.com/ (홈페이지 제작 문의) | I36: 경기 부천시 소사구 | J36: 캐릭터 토이 디자인, ABS/PVC 사출 피규어 양산, 소프트비닐·폴리레진 아트토이, 실리콘·러버 캐릭터 굿즈 | K36: 불명(소량~1천개 이상 대량 생산 가능 표기, 금형·양산 거점 미공개) | L36: 기업·프로스포츠·웹툰·지자체 캐릭터의 사출 피규어를 디자인해 양산하는 토이 디자인 업체로 금형·사출 양산은 중국 공장 의존도가 높아 소싱 파트너 수요가 크다. | M36: https://clawsup.com/ ; https://www.emis.com/php/company-profile/KR/Clawsup_Inc_en_23408343.html
A37: 36 | B37: 상 | C37: 허쉬위쉬(HUSHWISH) | D37: 캐릭터·IP·팬굿즈 기획사 | E37: https://www.hushwish.com/ | G37: hello@hushwish.com | H37: https://www.hushwish.com/contact_form/ (프로젝트 의뢰·제작 문의, 회사 계정 이메일만 접수) | J37: 캐릭터 개발·라이선싱, 기업 캐릭터 굿즈 기획, 이모티콘·애니메이션 콘텐츠 | K37: 불명(디자인·라이선싱 스튜디오로 생산 거점 언급 없음) | L37: 자체 라이선싱 캐릭터와 기업 캐릭터 굿즈를 기획하지만 제조 기능이 없는 디자인 스튜디오라 상품화 단계에서 중국 소싱 파트너가 필요하다. | M37: https://www.hushwish.com/contact_form/ ; https://www.hushwish.com/post_character/hushwish_licensing/
A38: 37 | B38: 상 | C38: 굿픽 스튜디오(GOODPIC STUDIO) | D38: 캐릭터·IP·팬굿즈 기획사 · 판촉물·굿즈 제작대행사 | E38: https://goodpicstudio.com/ | F38: 070-8244-9005 | G38: contact@goodpic.co.kr | H38: https://goodpicstudio.com/contact/ | J38: 굿즈 OEM/ODM 제작 전반(캐릭터·브랜드 굿즈) / 굿즈 OEM/ODM 기획·제작 | K38: 불명(OEM&ODM 전문 표기만 있고 생산 거점 언급 없음) | L38: OEM/ODM 굿즈 기획을 표방하는 소규모 스튜디오로 생산은 외부 공장에 의존하는 구조라 중국 소싱 파트너 제안에 열려 있을 가능성이 높다. / 소규모 OEM/ODM 굿즈 스튜디오로 자체 제조설비 언급이 없어 중국 생산 파트너 의존도가 높을 것으로 보인다. | M38: https://goodpicstudio.com/ ; https://goodpicstudio.com/contact/
A39: 38 | B39: 상 | C39: 다이버(DiiVER) | D39: 캐릭터·IP·팬굿즈 기획사 · 판촉물·굿즈 제작대행사 | E39: https://diiver.kr/ | F39: 02-466-0507 | G39: ask@diiver.kr | H39: https://diiver.kr/ (채팅 상담으로 견적 문의), https://diiver.kr/partner (파트너 입점) | I39: 서울 서대문구 | J39: 브랜드·캐릭터 굿즈 기획, 웰컴키트, 에코굿즈, 플레잉카드, 패키지·브랜딩 / 브랜드 굿즈 제작, 웰컴키트, 굿즈 스토어 운영대행 | K39: 약함(경기 고양 '다이버 팩토리' 국내 생산 거점 보유, 중국 거점 언급 없음) | L39: 국내 팩토리로 소량 제작은 자체 처리하지만 대량 IP 굿즈나 공산품 품목은 중국 소싱이 필요할 수 있어 보조 파트너로 접근 가능하다. / 브랜딩·디자인 중심의 굿즈 에이전시로 제조는 외주 구조라 중국 생산 파트너 확보 수요가 크다. | M39: https://diiver.kr/ ; https://www.diiver.kr/service
A40: 39 | B40: 상 | C40: 만상사 | D40: 캐릭터·IP·팬굿즈 기획사 · 판촉물·굿즈 제작대행사 | E40: https://mansangsa.com/ | F40: 1566-9437 | G40: biz@mansangsa.com | H40: https://mansangsa.com/ (홈페이지 상담 신청 폼) | I40: 서울 금천구 | J40: 게임·애니·웹툰·엔터 IP 굿즈, 인형/피규어 개발, OEM/ODM 상품, 단체복·키트, 해외 행사 MD / IP 굿즈, 기업 판촉물, 단체복, 웰컴키트, 인형·피규어 OEM/ODM | K40: 불명(전담 MD가 기획~검수·납품 일괄 진행, 자체 공장·중국 거점 언급 없음) | L40: 넥슨·크래프톤 등 IP 보유사 대상 인형·피규어·굿즈를 기획해 외주 생산하는 B2B 기획사로 자체 공장이 없어 중국 소싱 파트너가 필요할 가능성이 높다. / 국내 인쇄 설비 기반의 중견 굿즈 플랫폼이나 인형·피규어 등 해외 제작 품목은 외부 소싱망을 활용하므로 부분 협업 여지가 있다. | M40: https://mansangsa.com/about ; https://mansangsa.com/dolls-figures
...

Sheet 요약
A1: 카테고리별 업체 수
A2: 카테고리 | B2: 전체 | C2: 상 | D2: 중 | E2: 하 | F2: 연락완료 | G2: 관심/견적요청
A3: OEM 온라인브랜드·패키징 | B3: =COUNTIF(영업리스트!$D$2:$D$430,A3) | C3: =COUNTIFS(영업리스트!$D$2:$D$430,A3,영업리스트!$B$2:$B$430,"상") | D3: =COUNTIFS(영업리스트!$D$2:$D$430,A3,영업리스트!$B$2:$B$430,"중") | E3: =COUNTIFS(영업리스트!$D$2:$D$430,A3,영업리스트!$B$2:$B$430,"하") | F3: =COUNTIFS(영업리스트!$D$2:$D$430,A3,영업리스트!$Q$2:$Q$430,"<>") | G3: =COUNTIFS(영업리스트!$D$2:$D$430,A3,영업리스트!$Q$2:$Q$430,"관심")+COUNTIFS(영업리스트!$D$2:$D$430,A3,영업리스트!$Q$2:$Q$430,"견적요청")
A4: 관공서·학교·금융·프랜차이즈 판촉 납품업체 | B4: =COUNTIF(영업리스트!$D$2:$D$430,A4) | C4: =COUNTIFS(영업리스트!$D$2:$D$430,A4,영업리스트!$B$2:$B$430,"상") | D4: =COUNTIFS(영업리스트!$D$2:$D$430,A4,영업리스트!$B$2:$B$430,"중") | E4: =COUNTIFS(영업리스트!$D$2:$D$430,A4,영업리스트!$B$2:$B$430,"하") | F4: =COUNTIFS(영업리스트!$D$2:$D$430,A4,영업리스트!$Q$2:$Q$430,"<>") | G4: =COUNTIFS(영업리스트!$D$2:$D$430,A4,영업리스트!$Q$2:$Q$430,"관심")+COUNTIFS(영업리스트!$D$2:$D$430,A4,영업리스트!$Q$2:$Q$430,"견적요청")
A5: 광고·BTL·행사대행사 | B5: =COUNTIF(영업리스트!$D$2:$D$430,A5) | C5: =COUNTIFS(영업리스트!$D$2:$D$430,A5,영업리스트!$B$2:$B$430,"상") | D5: =COUNTIFS(영업리스트!$D$2:$D$430,A5,영업리스트!$B$2:$B$430,"중") | E5: =COUNTIFS(영업리스트!$D$2:$D$430,A5,영업리스트!$B$2:$B$430,"하") | F5: =COUNTIFS(영업리스트!$D$2:$D$430,A5,영업리스트!$Q$2:$Q$430,"<>") | G5: =COUNTIFS(영업리스트!$D$2:$D$430,A5,영업리스트!$Q$2:$Q$430,"관심")+COUNTIFS(영업리스트!$D$2:$D$430,A5,영업리스트!$Q$2:$Q$430,"견적요청")
A6: 무역·소싱대행·수입도매 | B6: =COUNTIF(영업리스트!$D$2:$D$430,A6) | C6: =COUNTIFS(영업리스트!$D$2:$D$430,A6,영업리스트!$B$2:$B$430,"상") | D6: =COUNTIFS(영업리스트!$D$2:$D$430,A6,영업리스트!$B$2:$B$430,"중") | E6: =COUNTIFS(영업리스트!$D$2:$D$430,A6,영업리스트!$B$2:$B$430,"하") | F6: =COUNTIFS(영업리스트!$D$2:$D$430,A6,영업리스트!$Q$2:$Q$430,"<>") | G6: =COUNTIFS(영업리스트!$D$2:$D$430,A6,영업리스트!$Q$2:$Q$430,"관심")+COUNTIFS(영업리스트!$D$2:$D$430,A6,영업리스트!$Q$2:$Q$430,"견적요청")
A7: 소규모 판촉물·패키징 중개벤더 | B7: =COUNTIF(영업리스트!$D$2:$D$430,A7) | C7: =COUNTIFS(영업리스트!$D$2:$D$430,A7,영업리스트!$B$2:$B$430,"상") | D7: =COUNTIFS(영업리스트!$D$2:$D$430,A7,영업리스트!$B$2:$B$430,"중") | E7: =COUNTIFS(영업리스트!$D$2:$D$430,A7,영업리스트!$B$2:$B$430,"하") | F7: =COUNTIFS(영업리스트!$D$2:$D$430,A7,영업리스트!$Q$2:$Q$430,"<>") | G7: =COUNTIFS(영업리스트!$D$2:$D$430,A7,영업리스트!$Q$2:$Q$430,"관심")+COUNTIFS(영업리스트!$D$2:$D$430,A7,영업리스트!$Q$2:$Q$430,"견적요청")
A8: 스포츠·헬스·재활용품 유통사/OEM브랜드 | B8: =COUNTIF(영업리스트!$D$2:$D$430,A8) | C8: =COUNTIFS(영업리스트!$D$2:$D$430,A8,영업리스트!$B$2:$B$430,"상") | D8: =COUNTIFS(영업리스트!$D$2:$D$430,A8,영업리스트!$B$2:$B$430,"중") | E8: =COUNTIFS(영업리스트!$D$2:$D$430,A8,영업리스트!$B$2:$B$430,"하") | F8: =COUNTIFS(영업리스트!$D$2:$D$430,A8,영업리스트!$Q$2:$Q$430,"<>") | G8: =COUNTIFS(영업리스트!$D$2:$D$430,A8,영업리스트!$Q$2:$Q$430,"관심")+COUNTIFS(영업리스트!$D$2:$D$430,A8,영업리스트!$Q$2:$Q$430,"견적요청")
A9: 제약·의료·치과 판촉물 벤더 | B9: =COUNTIF(영업리스트!$D$2:$D$430,A9) | C9: =COUNTIFS(영업리스트!$D$2:$D$430,A9,영업리스트!$B$2:$B$430,"상") | D9: =COUNTIFS(영업리스트!$D$2:$D$430,A9,영업리스트!$B$2:$B$430,"중") | E9: =COUNTIFS(영업리스트!$D$2:$D$430,A9,영업리스트!$B$2:$B$430,"하") | F9: =COUNTIFS(영업리스트!$D$2:$D$430,A9,영업리스트!$Q$2:$Q$430,"<>") | G9: =COUNTIFS(영업리스트!$D$2:$D$430,A9,영업리스트!$Q$2:$Q$430,"관심")+COUNTIFS(영업리스트!$D$2:$D$430,A9,영업리스트!$Q$2:$Q$430,"견적요청")
A10: 캐릭터·IP·팬굿즈 기획사 | B10: =COUNTIF(영업리스트!$D$2:$D$430,A10) | C10: =COUNTIFS(영업리스트!$D$2:$D$430,A10,영업리스트!$B$2:$B$430,"상") | D10: =COUNTIFS(영업리스트!$D$2:$D$430,A10,영업리스트!$B$2:$B$430,"중") | E10: =COUNTIFS(영업리스트!$D$2:$D$430,A10,영업리스트!$B$2:$B$430,"하") | F10: =COUNTIFS(영업리스트!$D$2:$D$430,A10,영업리스트!$Q$2:$Q$430,"<>") | G10: =COUNTIFS(영업리스트!$D$2:$D$430,A10,영업리스트!$Q$2:$Q$430,"관심")+COUNTIFS(영업리스트!$D$2:$D$430,A10,영업리스트!$Q$2:$Q$430,"견적요청")
A11: 캐릭터·IP·팬굿즈 기획사 · 소규모 판촉물·패키징 중개벤더 | B11: =COUNTIF(영업리스트!$D$2:$D$430,A11) | C11: =COUNTIFS(영업리스트!$D$2:$D$430,A11,영업리스트!$B$2:$B$430,"상") | D11: =COUNTIFS(영업리스트!$D$2:$D$430,A11,영업리스트!$B$2:$B$430,"중") | E11: =COUNTIFS(영업리스트!$D$2:$D$430,A11,영업리스트!$B$2:$B$430,"하") | F11: =COUNTIFS(영업리스트!$D$2:$D$430,A11,영업리스트!$Q$2:$Q$430,"<>") | G11: =COUNTIFS(영업리스트!$D$2:$D$430,A11,영업리스트!$Q$2:$Q$430,"관심")+COUNTIFS(영업리스트!$D$2:$D$430,A11,영업리스트!$Q$2:$Q$430,"견적요청")
A12: 캐릭터·IP·팬굿즈 기획사 · 판촉물·굿즈 제작대행사 | B12: =COUNTIF(영업리스트!$D$2:$D$430,A12) | C12: =COUNTIFS(영업리스트!$D$2:$D$430,A12,영업리스트!$B$2:$B$430,"상") | D12: =COUNTIFS(영업리스트!$D$2:$D$430,A12,영업리스트!$B$2:$B$430,"중") | E12: =COUNTIFS(영업리스트!$D$2:$D$430,A12,영업리스트!$B$2:$B$430,"하") | F12: =COUNTIFS(영업리스트!$D$2:$D$430,A12,영업리스트!$Q$2:$Q$430,"<>") | G12: =COUNTIFS(영업리스트!$D$2:$D$430,A12,영업리스트!$Q$2:$Q$430,"관심")+COUNTIFS(영업리스트!$D$2:$D$430,A12,영업리스트!$Q$2:$Q$430,"견적요청")
A13: 판촉물·굿즈 제작대행사 | B13: =COUNTIF(영업리스트!$D$2:$D$430,A13) | C13: =COUNTIFS(영업리스트!$D$2:$D$430,A13,영업리스트!$B$2:$B$430,"상") | D13: =COUNTIFS(영업리스트!$D$2:$D$430,A13,영업리스트!$B$2:$B$430,"중") | E13: =COUNTIFS(영업리스트!$D$2:$D$430,A13,영업리스트!$B$2:$B$430,"하") | F13: =COUNTIFS(영업리스트!$D$2:$D$430,A13,영업리스트!$Q$2:$Q$430,"<>") | G13: =COUNTIFS(영업리스트!$D$2:$D$430,A13,영업리스트!$Q$2:$Q$430,"관심")+COUNTIFS(영업리스트!$D$2:$D$430,A13,영업리스트!$Q$2:$Q$430,"견적요청")
A14: 판촉물·굿즈 제작대행사 · 관공서·학교·금융·프랜차이즈 판촉 납품업체 | B14: =COUNTIF(영업리스트!$D$2:$D$430,A14) | C14: =COUNTIFS(영업리스트!$D$2:$D$430,A14,영업리스트!$B$2:$B$430,"상") | D14: =COUNTIFS(영업리스트!$D$2:$D$430,A14,영업리스트!$B$2:$B$430,"중") | E14: =COUNTIFS(영업리스트!$D$2:$D$430,A14,영업리스트!$B$2:$B$430,"하") | F14: =COUNTIFS(영업리스트!$D$2:$D$430,A14,영업리스트!$Q$2:$Q$430,"<>") | G14: =COUNTIFS(영업리스트!$D$2:$D$430,A14,영업리스트!$Q$2:$Q$430,"관심")+COUNTIFS(영업리스트!$D$2:$D$430,A14,영업리스트!$Q$2:$Q$430,"견적요청")
A15: 회수 대상(前 파트너 거래처) | B15: =COUNTIF(영업리스트!$D$2:$D$430,A15) | C15: =COUNTIFS(영업리스트!$D$2:$D$430,A15,영업리스트!$B$2:$B$430,"상") | D15: =COUNTIFS(영업리스트!$D$2:$D$430,A15,영업리스트!$B$2:$B$430,"중") | E15: =COUNTIFS(영업리스트!$D$2:$D$430,A15,영업리스트!$B$2:$B$430,"하") | F15: =COUNTIFS(영업리스트!$D$2:$D$430,A15,영업리스트!$Q$2:$Q$430,"<>") | G15: =COUNTIFS(영업리스트!$D$2:$D$430,A15,영업리스트!$Q$2:$Q$430,"관심")+COUNTIFS(영업리스트!$D$2:$D$430,A15,영업리스트!$Q$2:$Q$430,"견적요청")
A16: 합계 | B16: =SUM(B3:B15) | C16: =SUM(C3:C15) | D16: =SUM(D3:D15) | E16: =SUM(E3:E15) | F16: =SUM(F3:F15) | G16: =SUM(G3:G15)
A18: 연락결과 현황
A19: 결과 | B19: 건수
A20: 통화 | B20: =COUNTIF(영업리스트!$Q$2:$Q$430,A20)
A21: 메일발송 | B21: =COUNTIF(영업리스트!$Q$2:$Q$430,A21)
A22: 관심 | B22: =COUNTIF(영업리스트!$Q$2:$Q$430,A22)
A23: 견적요청 | B23: =COUNTIF(영업리스트!$Q$2:$Q$430,A23)
A24: 거절 | B24: =COUNTIF(영업리스트!$Q$2:$Q$430,A24)
A25: 부재 | B25: =COUNTIF(영업리스트!$Q$2:$Q$430,A25)
A26: 재연락 | B26: =COUNTIF(영업리스트!$Q$2:$Q$430,A26)

Sheet 영업멘트
A1: 포지션 한 줄 | B1: 품목에 상관없이, 한국에서 필요한 제품과 사양만 주시면 중국 현지 제조공장 발굴 → 샘플 → 가격협상 → 생산 → 검수 → 통관·국내 납품까지 한 번에 연결하는 회사. (보호대는 '우리가 실제로 중국에서 만들어 팔고 있다'는 증거로만 언급)
A2: 전화 첫 멘트 | B2: 안녕하세요, 올투게더나우 대표 ○○○입니다. 저희는 중국 현지 제조 파트너와 함께 굿즈·판촉물·패키지·생활용품·봉제·전자소품 등 품목 가리지 않고 공장 발굴부터 샘플, 생산, 검수, 국내 입고까지 한 번에 진행하는 회사입니다. 저희 자체 제품도 같은 방식으로 중국에서 만들어 네이버·쿠팡에서 팔고 있어서 품질·납기 관리는 직접 겪어본 경험이 있습니다. 귀사에서 중국 생산이 들어가는 건이 있으면 견적 비교부터 도와드리고 싶은데, 구매 담당 부서로 연결 가능할까요?
A3: 핵심 차별점 | B3: 1) 단순 구매대행이 아니라 중국 현지 제조 파트너가 직접 공장을 찾고 생산을 관리. 2) 품목 제한 없음: 인쇄물·잡화·봉제·사출·금속·패키지·전자소품까지 공장 네트워크로 대응. 3) 저희도 자체 제품을 중국에서 만들어 파는 회사라 사고 유형(불량, 납기, 인증)을 알고 미리 막음. 4) 수출입 사업자로 세금계산서 발행, 통관, KC 인증 안내까지 국내에서 처리.
A4: 이메일 제목 | B4: [제안] 중국 OEM 생산 원스톱 대행 (공장 발굴~검수~국내 납품, 품목 무관) - 올투게더나우
A5: 이메일 본문 | B5: 안녕하세요, 올투게더나우 대표 ○○○입니다. 저희는 중국 현지 제조 파트너와 함께, 품목에 상관없이 중국 생산이 필요한 제품을 아래 과정으로 원스톱 진행해 드립니다. 1. 제품·사양·수량·예산만 알려주시면 중국 현지 파트너가 제조공장을 발굴 2. 샘플 제작 및 국내 발송 3. 가격 협상 및 견적서 제출 4. 생산 진행 및 출하 전 검수 (사진·영상 보고) 5. 통관 후 국내 지정 장소 납품, 세금계산서 발행 대응 품목: 판촉물·굿즈(인쇄, 아크릴, 금속, 봉제, 사출), 패키지(박스·쇼핑백·파우치), 생활용품·주방용품, 스포츠·헬스용품, 전자소품(보조배터리·케이블 등) 외 다수. 저희 자체 브랜드 제품도 같은 방식으로 중국에서 생산해 네이버·쿠팡에서 판매 중이라, 품질·납기 관리는 직접 겪어본 노하우로 진행합니다. 진행 중인 건 하나로 견적 비교부터 해보셔도 좋습니다. 연락 주시면 바로 찾아뵙고 설명드리겠습니다. 올투게더나우 대표 ○○○ / 전화 000-0000-0000 / 이메일 ○○○@○○○
A6: 예상 질문 1 | B6: Q. 이미 거래하는 중국 공장이 있는데요? → A. 그러면 견적 비교용으로만 한 건 받아보세요. 같은 사양으로 저희 견적이 더 낮거나 납기가 빠르면 그때 바꾸시면 됩니다.
A7: 예상 질문 2 | B7: Q. 소량도 되나요? → A. 품목별로 다르지만 300~500개부터 가능한 공장을 찾아드립니다. 우선 사양 주시면 MOQ부터 확인해 드릴게요.
A8: 예상 질문 3 | B8: Q. 불량 나면 어떻게 하나요? → A. 출하 전 검수 사진·영상을 보내드리고, 검수 통과 후에만 출고합니다. 계약서에 불량 시 재생산 조건을 명시합니다.
A9: 예상 질문 4 | B9: Q. 무슨 품목까지 되나요? → A. 저희가 하는 건 특정 제품이 아니라 '공장을 찾아 생산을 관리하는 일'이라 품목 제한이 없습니다. 지금 진행 중인 품목 말씀해 주시면 그 공장부터 찾아드립니다.
A10: 회수 대상 멘트 | B10: 안녕하세요, 올투게더나우 ○○○ 대표입니다. 그동안 함석민 님을 통해 진행하셨던 중국 생산 건(예: 클립펜·온습도계, 캐릭터 굿즈, 패키지 박스)은 실제로는 저희 중국 파트너 리자위 공장에서 만들어졌습니다. 현재 함석민 님과는 거래가 정리되어, 앞으로는 저희가 한국 창구를 맡아 같은 공장·같은 품질로 직접 진행해 드립니다. 중간 단계가 하나 빠지는 만큼 단가와 소통 속도 모두 유리합니다. 진행 중이거나 예정된 건 있으시면 바로 견적 드리겠습니다.
A11: 회수 대상 주의 | B11: 1) 前 파트너 험담은 하지 말고 '거래가 정리됐다'까지만. 2) 상대가 함석민과 계속 거래 중일 수 있으니 첫 통화는 탐색 위주로. 3) 과거 생산 사진·샘플을 리자위에게 미리 받아두면 '같은 공장' 증명이 바로 됩니다. 4) 개인 휴대폰보다 회사 번호·메일로 먼저 연락.
A12: 후속 조치 | B12: 통화 후 24시간 안에 이메일로 회사소개(중국 공장 사진, 생산 사례 사진, 자사 제품 판매 페이지) + 견적 요청 양식(품목/사양/수량/희망단가/납기) 발송. 1주 뒤 재연락.
